Workbook

Sheet Instructions
A1: TEXNICA TPCS 1.0 — FABRIC CONTROL WORKBOOK
A3: Purpose | B3: Operational workbook for FGPO, fabric requirement, purchasing, mill production, shipment, Texnica receiving, testing, approval, inventory and cutting issuance.
A4: 1. Start | B4: Create the customer order in FGPO Master. If no official number exists, select FGPO Pending and use a unique Temporary Order ID.
A5: 2. Requirement | B5: Enter style consumption in Fabric Requirement. Gross and net purchase quantities calculate automatically.
A6: 3. Purchase | B6: Create Fabric PO records and allocate ordered quantities to FGPOs.
A7: 4. Mill | B7: Update production by Fabric PO, FGPO and Lot. Record the mill test separately.
A8: 5. Logistics | B8: Record fabric shipment and In Transit quantities by Lot.
A9: 6. Receiving | B9: Receive at Texnica by shipment and then by individual Roll.
A10: 7. Quality | B10: Complete Four-Point, Internal Test and Shade Match records.
A11: 8. Approval | B11: Fabric Approval calculates whether all gates are passed before Release for Cutting.
A12: 9. Inventory | B12: Fabric Inventory consolidates approved, hold, reserved, issued, returned and available quantities.
A13: 10. Cutting | B13: Issue only approved and available fabric to cutting.
A14: Shipment Variance | B14: Total Shipped Quantity − Order Quantity. Negative = pending; positive = over-shipment.
... A19: Capacity | B19: Each operational sheet provides 300 working rows.

Sheet Dashboard
A1: TEXNICA PRODUCTION CONTROL SYSTEM — MASTER DASHBOARD
A2: Customer PO visibility from material development through shipment. Click sheet tabs for full operational detail.
A4: Open FGPO | D4: Order Quantity | G4: Cut Quantity | J4: Sewing Output | M4: Packed Quantity | P4: In Transit | S4: Customer Received
A5: =COUNTA('FGPO Master'!A5:A304)-COUNTIF('FGPO Master'!D5:D304,"Closed") -> 0 | D5: =SUM('FGPO Master'!H5:H304) -> 0 | G5: =SUM('Cutting Control'!K5:K304) -> 0 | J5: =SUM('Sewing Production'!L5:L304) -> 0 | M5: =SUM('Packing Control'!K5:K304) -> 0 | P5: =SUM('Shipment Control'!I5:I304) -> 0 | S5: =SUM('Shipment Control'!J5:J304) -> 0
A10: FGPO | B10: Style | C10: Color | D10: Order Qty | E10: Fabric Status | F10: Trims Status | G10: PP Sample | H10: PRR | I10: Cutting Release | J10: Cut Qty | K10: TOP Sample | L10: Sewing Qty | M10: Inline QC | N10: Final QC | O10: Packed Qty | P10: Ready to Ship | Q10: In Transit | R10: Received Qty | S10: Shipment Variance | T10: Ship Date | U10: Risk | V10: Last Updated
A11: =IF('FGPO Master'!A5="","",IF('FGPO Master'!D5="FGPO Pending","FGPO Pending",'FGPO Master'!B5)) | B11: =IF('FGPO Master'!A5="","",'FGPO Master'!F5) | C11: =IF('FGPO Master'!A5="","",'FGPO Master'!G5) | D11: =IF('FGPO Master'!A5="","",'FGPO Master'!H5) | E11: =IF(A11="","",IF(SUMIF('Fabric Inventory'!$C$5:$C$304,A11,'Fabric Inventory'!$O$5:$O$304)>0,"Shortage",IF(SUMIF('Fabric Inventory'!$C$5:$C$304,A11,'Fabric Inventory'!$H$5:$H$304)>0,"Approved","Pending"))) | F11: =IF(A11="","",IF(SUMIF('Trims Control'!$B$5:$B$304,A11,'Trims Control'!$R$5:$R$304)>0,"Shortage",IF(COUNTIFS('Trims Control'!$B$5:$B$304,A11,'Trims Control'!$V$5:$V$304,"Ready")>0,"Ready","Pending"))) | G11: =IF(A11="","",IFERROR(INDEX('PP Sample'!$V$5:$V$304,MATCH(A11,'PP Sample'!$B$5:$B$304,0)),"Pending")) | H11: =IF(A11="","",IFERROR(INDEX('Production Readiness'!$S$5:$S$304,MATCH(A11,'Production Readiness'!$C$5:$C$304,0)),"Pending")) | I11: =IF(A11="","",IFERROR(INDEX('Cutting Release'!$P$5:$P$304,MATCH(A11,'Cutting Release'!$C$5:$C$304,0)),"Pending")) | J11: =IF(A11="","",SUMIF('Cutting Control'!$C$5:$C$304,A11,'Cutting Control'!$K$5:$K$304)) | K11: =IF(A11="","",IFERROR(INDEX('TOP Sample'!$W$5:$W$304,MATCH(A11,'TOP Sample'!$B$5:$B$304,0)),"Pending")) | L11: =IF(A11="","",SUMIF('Sewing Production'!$E$5:$E$304,A11,'Sewing Production'!$L$5:$L$304)) | M11: =IF(A11="","",IFERROR(INDEX('Inline Quality'!$S$5:$S$304,MATCH(A11,'Inline Quality'!$E$5:$E$304,0)),"Pending")) | N11: =IF(A11="","",IFERROR(INDEX('Final Inspection'!$U$5:$U$304,MATCH(A11,'Final Inspection'!$C$5:$C$304,0)),"Pending")) | O11: =IF(A11="","",SUMIF('Packing Control'!$C$5:$C$304,A11,'Packing Control'!$K$5:$K$304)) | P11: =IF(A11="","",SUMIF('Finished Goods'!$C$5:$C$304,A11,'Finished Goods'!$J$5:$J$304)) | Q11: =IF(A11="","",SUMIF('Shipment Control'!$C$5:$C$304,A11,'Shipment Control'!$I$5:$I$304)) | R11: =IF(A11="","",SUMIF('Shipment Control'!$C$5:$C$304,A11,'Shipment Control'!$J$5:$J$304)) | S11: =IF(A11="","",Q11+R11-D11) | T11: =IF('FGPO Master'!A5="","",'FGPO Master'!I5) | U11: =IF(A11="","",IF(COUNTIF('Open Issues'!$D$5:$D$304,A11)>0,"Yellow","Green")) | V11: =IF('FGPO Master'!A5="","",'FGPO Master'!U5)
A12: =IF('FGPO Master'!A6="","",IF('FGPO Master'!D6="FGPO Pending","FGPO Pending",'FGPO Master'!B6)) | B12: =IF('FGPO Master'!A6="","",'FGPO Master'!F6) | C12: =IF('FGPO Master'!A6="","",'FGPO Master'!G6) | D12: =IF('FGPO Master'!A6="","",'FGPO Master'!H6) | E12: =IF(A12="","",IF(SUMIF('Fabric Inventory'!$C$5:$C$304,A12,'Fabric Inventory'!$O$5:$O$304)>0,"Shortage",IF(SUMIF('Fabric Inventory'!$C$5:$C$304,A12,'Fabric Inventory'!$H$5:$H$304)>0,"Approved","Pending"))) | F12: =IF(A12="","",IF(SUMIF('Trims Control'!$B$5:$B$304,A12,'Trims Control'!$R$5:$R$304)>0,"Shortage",IF(COUNTIFS('Trims Control'!$B$5:$B$304,A12,'Trims Control'!$V$5:$V$304,"Ready")>0,"Ready","Pending"))) | G12: =IF(A12="","",IFERROR(INDEX('PP Sample'!$V$5:$V$304,MATCH(A12,'PP Sample'!$B$5:$B$304,0)),"Pending")) | H12: =IF(A12="","",IFERROR(INDEX('Production Readiness'!$S$5:$S$304,MATCH(A12,'Production Readiness'!$C$5:$C$304,0)),"Pending")) | I12: =IF(A12="","",IFERROR(INDEX('Cutting Release'!$P$5:$P$304,MATCH(A12,'Cutting Release'!$C$5:$C$304,0)),"Pending")) | J12: =IF(A12="","",SUMIF('Cutting Control'!$C$5:$C$304,A12,'Cutting Control'!$K$5:$K$304)) | K12: =IF(A12="","",IFERROR(INDEX('TOP Sample'!$W$5:$W$304,MATCH(A12,'TOP Sample'!$B$5:$B$304,0)),"Pending")) | L12: =IF(A12="","",SUMIF('Sewing Production'!$E$5:$E$304,A12,'Sewing Production'!$L$5:$L$304)) | M12: =IF(A12="","",IFERROR(INDEX('Inline Quality'!$S$5:$S$304,MATCH(A12,'Inline Quality'!$E$5:$E$304,0)),"Pending")) | N12: =IF(A12="","",IFERROR(INDEX('Final Inspection'!$U$5:$U$304,MATCH(A12,'Final Inspection'!$C$5:$C$304,0)),"Pending")) | O12: =IF(A12="","",SUMIF('Packing Control'!$C$5:$C$304,A12,'Packing Control'!$K$5:$K$304)) | P12: =IF(A12="","",SUMIF('Finished Goods'!$C$5:$C$304,A12,'Finished Goods'!$J$5:$J$304)) | Q12: =IF(A12="","",SUMIF('Shipment Control'!$C$5:$C$304,A12,'Shipment Control'!$I$5:$I$304)) | R12: =IF(A12="","",SUMIF('Shipment Control'!$C$5:$C$304,A12,'Shipment Control'!$J$5:$J$304)) | S12: =IF(A12="","",Q12+R12-D12) | T12: =IF('FGPO Master'!A6="","",'FGPO Master'!I6) | U12: =IF(A12="","",IF(COUNTIF('Open Issues'!$D$5:$D$304,A12)>0,"Yellow","Green")) | V12: =IF('FGPO Master'!A6="","",'FGPO Master'!U6)
A13: =IF('FGPO Master'!A7="","",IF('FGPO Master'!D7="FGPO Pending","FGPO Pending",'FGPO Master'!B7)) | B13: =IF('FGPO Master'!A7="","",'FGPO Master'!F7) | C13: =IF('FGPO Master'!A7="","",'FGPO Master'!G7) | D13: =IF('FGPO Master'!A7="","",'FGPO Master'!H7) | E13: =IF(A13="","",IF(SUMIF('Fabric Inventory'!$C$5:$C$304,A13,'Fabric Inventory'!$O$5:$O$304)>0,"Shortage",IF(SUMIF('Fabric Inventory'!$C$5:$C$304,A13,'Fabric Inventory'!$H$5:$H$304)>0,"Approved","Pending"))) | F13: =IF(A13="","",IF(SUMIF('Trims Control'!$B$5:$B$304,A13,'Trims Control'!$R$5:$R$304)>0,"Shortage",IF(COUNTIFS('Trims Control'!$B$5:$B$304,A13,'Trims Control'!$V$5:$V$304,"Ready")>0,"Ready","Pending"))) | G13: =IF(A13="","",IFERROR(INDEX('PP Sample'!$V$5:$V$304,MATCH(A13,'PP Sample'!$B$5:$B$304,0)),"Pending")) | H13: =IF(A13="","",IFERROR(INDEX('Production Readiness'!$S$5:$S$304,MATCH(A13,'Production Readiness'!$C$5:$C$304,0)),"Pending")) | I13: =IF(A13="","",IFERROR(INDEX('Cutting Release'!$P$5:$P$304,MATCH(A13,'Cutting Release'!$C$5:$C$304,0)),"Pending")) | J13: =IF(A13="","",SUMIF('Cutting Control'!$C$5:$C$304,A13,'Cutting Control'!$K$5:$K$304)) | K13: =IF(A13="","",IFERROR(INDEX('TOP Sample'!$W$5:$W$304,MATCH(A13,'TOP Sample'!$B$5:$B$304,0)),"Pending")) | L13: =IF(A13="","",SUMIF('Sewing Production'!$E$5:$E$304,A13,'Sewing Production'!$L$5:$L$304)) | M13: =IF(A13="","",IFERROR(INDEX('Inline Quality'!$S$5:$S$304,MATCH(A13,'Inline Quality'!$E$5:$E$304,0)),"Pending")) | N13: =IF(A13="","",IFERROR(INDEX('Final Inspection'!$U$5:$U$304,MATCH(A13,'Final Inspection'!$C$5:$C$304,0)),"Pending")) | O13: =IF(A13="","",SUMIF('Packing Control'!$C$5:$C$304,A13,'Packing Control'!$K$5:$K$304)) | P13: =IF(A13="","",SUMIF('Finished Goods'!$C$5:$C$304,A13,'Finished Goods'!$J$5:$J$304)) | Q13: =IF(A13="","",SUMIF('Shipment Control'!$C$5:$C$304,A13,'Shipment Control'!$I$5:$I$304)) | R13: =IF(A13="","",SUMIF('Shipment Control'!$C$5:$C$304,A13,'Shipment Control'!$J$5:$J$304)) | S13: =IF(A13="","",Q13+R13-D13) | T13: =IF('FGPO Master'!A7="","",'FGPO Master'!I7) | U13: =IF(A13="","",IF(COUNTIF('Open Issues'!$D$5:$D$304,A13)>0,"Yellow","Green")) | V13: =IF('FGPO Master'!A7="","",'FGPO Master'!U7)
A14: =IF('FGPO Master'!A8="","",IF('FGPO Master'!D8="FGPO Pending","FGPO Pending",'FGPO Master'!B8)) | B14: =IF('FGPO Master'!A8="","",'FGPO Master'!F8) | C14: =IF('FGPO Master'!A8="","",'FGPO Master'!G8) | D14: =IF('FGPO Master'!A8="","",'FGPO Master'!H8) | E14: =IF(A14="","",IF(SUMIF('Fabric Inventory'!$C$5:$C$304,A14,'Fabric Inventory'!$O$5:$O$304)>0,"Shortage",IF(SUMIF('Fabric Inventory'!$C$5:$C$304,A14,'Fabric Inventory'!$H$5:$H$304)>0,"Approved","Pending"))) | F14: =IF(A14="","",IF(SUMIF('Trims Control'!$B$5:$B$304,A14,'Trims Control'!$R$5:$R$304)>0,"Shortage",IF(COUNTIFS('Trims Control'!$B$5:$B$304,A14,'Trims Control'!$V$5:$V$304,"Ready")>0,"Ready","Pending"))) | G14: =IF(A14="","",IFERROR(INDEX('PP Sample'!$V$5:$V$304,MATCH(A14,'PP Sample'!$B$5:$B$304,0)),"Pending")) | H14: =IF(A14="","",IFERROR(INDEX('Production Readiness'!$S$5:$S$304,MATCH(A14,'Production Readiness'!$C$5:$C$304,0)),"Pending")) | I14: =IF(A14="","",IFERROR(INDEX('Cutting Release'!$P$5:$P$304,MATCH(A14,'Cutting Release'!$C$5:$C$304,0)),"Pending")) | J14: =IF(A14="","",SUMIF('Cutting Control'!$C$5:$C$304,A14,'Cutting Control'!$K$5:$K$304)) | K14: =IF(A14="","",IFERROR(INDEX('TOP Sample'!$W$5:$W$304,MATCH(A14,'TOP Sample'!$B$5:$B$304,0)),"Pending")) | L14: =IF(A14="","",SUMIF('Sewing Production'!$E$5:$E$304,A14,'Sewing Production'!$L$5:$L$304)) | M14: =IF(A14="","",IFERROR(INDEX('Inline Quality'!$S$5:$S$304,MATCH(A14,'Inline Quality'!$E$5:$E$304,0)),"Pending")) | N14: =IF(A14="","",IFERROR(INDEX('Final Inspection'!$U$5:$U$304,MATCH(A14,'Final Inspection'!$C$5:$C$304,0)),"Pending")) | O14: =IF(A14="","",SUMIF('Packing Control'!$C$5:$C$304,A14,'Packing Control'!$K$5:$K$304)) | P14: =IF(A14="","",SUMIF('Finished Goods'!$C$5:$C$304,A14,'Finished Goods'!$J$5:$J$304)) | Q14: =IF(A14="","",SUMIF('Shipment Control'!$C$5:$C$304,A14,'Shipment Control'!$I$5:$I$304)) | R14: =IF(A14="","",SUMIF('Shipment Control'!$C$5:$C$304,A14,'Shipment Control'!$J$5:$J$304)) | S14: =IF(A14="","",Q14+R14-D14) | T14: =IF('FGPO Master'!A8="","",'FGPO Master'!I8) | U14: =IF(A14="","",IF(COUNTIF('Open Issues'!$D$5:$D$304,A14)>0,"Yellow","Green")) | V14: =IF('FGPO Master'!A8="","",'FGPO Master'!U8)
A15: =IF('FGPO Master'!A9="","",IF('FGPO Master'!D9="FGPO Pending","FGPO Pending",'FGPO Master'!B9)) | B15: =IF('FGPO Master'!A9="","",'FGPO Master'!F9) | C15: =IF('FGPO Master'!A9="","",'FGPO Master'!G9) | D15: =IF('FGPO Master'!A9="","",'FGPO Master'!H9) | E15: =IF(A15="","",IF(SUMIF('Fabric Inventory'!$C$5:$C$304,A15,'Fabric Inventory'!$O$5:$O$304)>0,"Shortage",IF(SUMIF('Fabric Inventory'!$C$5:$C$304,A15,'Fabric Inventory'!$H$5:$H$304)>0,"Approved","Pending"))) | F15: =IF(A15="","",IF(SUMIF('Trims Control'!$B$5:$B$304,A15,'Trims Control'!$R$5:$R$304)>0,"Shortage",IF(COUNTIFS('Trims Control'!$B$5:$B$304,A15,'Trims Control'!$V$5:$V$304,"Ready")>0,"Ready","Pending"))) | G15: =IF(A15="","",IFERROR(INDEX('PP Sample'!$V$5:$V$304,MATCH(A15,'PP Sample'!$B$5:$B$304,0)),"Pending")) | H15: =IF(A15="","",IFERROR(INDEX('Production Readiness'!$S$5:$S$304,MATCH(A15,'Production Readiness'!$C$5:$C$304,0)),"Pending")) | I15: =IF(A15="","",IFERROR(INDEX('Cutting Release'!$P$5:$P$304,MATCH(A15,'Cutting Release'!$C$5:$C$304,0)),"Pending")) | J15: =IF(A15="","",SUMIF('Cutting Control'!$C$5:$C$304,A15,'Cutting Control'!$K$5:$K$304)) | K15: =IF(A15="","",IFERROR(INDEX('TOP Sample'!$W$5:$W$304,MATCH(A15,'TOP Sample'!$B$5:$B$304,0)),"Pending")) | L15: =IF(A15="","",SUMIF('Sewing Production'!$E$5:$E$304,A15,'Sewing Production'!$L$5:$L$304)) | M15: =IF(A15="","",IFERROR(INDEX('Inline Quality'!$S$5:$S$304,MATCH(A15,'Inline Quality'!$E$5:$E$304,0)),"Pending")) | N15: =IF(A15="","",IFERROR(INDEX('Final Inspection'!$U$5:$U$304,MATCH(A15,'Final Inspection'!$C$5:$C$304,0)),"Pending")) | O15: =IF(A15="","",SUMIF('Packing Control'!$C$5:$C$304,A15,'Packing Control'!$K$5:$K$304)) | P15: =IF(A15="","",SUMIF('Finished Goods'!$C$5:$C$304,A15,'Finished Goods'!$J$5:$J$304)) | Q15: =IF(A15="","",SUMIF('Shipment Control'!$C$5:$C$304,A15,'Shipment Control'!$I$5:$I$304)) | R15: =IF(A15="","",SUMIF('Shipment Control'!$C$5:$C$304,A15,'Shipment Control'!$J$5:$J$304)) | S15: =IF(A15="","",Q15+R15-D15) | T15: =IF('FGPO Master'!A9="","",'FGPO Master'!I9) | U15: =IF(A15="","",IF(COUNTIF('Open Issues'!$D$5:$D$304,A15)>0,"Yellow","Green")) | V15: =IF('FGPO Master'!A9="","",'FGPO Master'!U9)
A16: =IF('FGPO Master'!A10="","",IF('FGPO Master'!D10="FGPO Pending","FGPO Pending",'FGPO Master'!B10)) | B16: =IF('FGPO Master'!A10="","",'FGPO Master'!F10) | C16: =IF('FGPO Master'!A10="","",'FGPO Master'!G10) | D16: =IF('FGPO Master'!A10="","",'FGPO Master'!H10) | E16: =IF(A16="","",IF(SUMIF('Fabric Inventory'!$C$5:$C$304,A16,'Fabric Inventory'!$O$5:$O$304)>0,"Shortage",IF(SUMIF('Fabric Inventory'!$C$5:$C$304,A16,'Fabric Inventory'!$H$5:$H$304)>0,"Approved","Pending"))) | F16: =IF(A16="","",IF(SUMIF('Trims Control'!$B$5:$B$304,A16,'Trims Control'!$R$5:$R$304)>0,"Shortage",IF(COUNTIFS('Trims Control'!$B$5:$B$304,A16,'Trims Control'!$V$5:$V$304,"Ready")>0,"Ready","Pending"))) | G16: =IF(A16="","",IFERROR(INDEX('PP Sample'!$V$5:$V$304,MATCH(A16,'PP Sample'!$B$5:$B$304,0)),"Pending")) | H16: =IF(A16="","",IFERROR(INDEX('Production Readiness'!$S$5:$S$304,MATCH(A16,'Production Readiness'!$C$5:$C$304,0)),"Pending")) | I16: =IF(A16="","",IFERROR(INDEX('Cutting Release'!$P$5:$P$304,MATCH(A16,'Cutting Release'!$C$5:$C$304,0)),"Pending")) | J16: =IF(A16="","",SUMIF('Cutting Control'!$C$5:$C$304,A16,'Cutting Control'!$K$5:$K$304)) | K16: =IF(A16="","",IFERROR(INDEX('TOP Sample'!$W$5:$W$304,MATCH(A16,'TOP Sample'!$B$5:$B$304,0)),"Pending")) | L16: =IF(A16="","",SUMIF('Sewing Production'!$E$5:$E$304,A16,'Sewing Production'!$L$5:$L$304)) | M16: =IF(A16="","",IFERROR(INDEX('Inline Quality'!$S$5:$S$304,MATCH(A16,'Inline Quality'!$E$5:$E$304,0)),"Pending")) | N16: =IF(A16="","",IFERROR(INDEX('Final Inspection'!$U$5:$U$304,MATCH(A16,'Final Inspection'!$C$5:$C$304,0)),"Pending")) | O16: =IF(A16="","",SUMIF('Packing Control'!$C$5:$C$304,A16,'Packing Control'!$K$5:$K$304)) | P16: =IF(A16="","",SUMIF('Finished Goods'!$C$5:$C$304,A16,'Finished Goods'!$J$5:$J$304)) | Q16: =IF(A16="","",SUMIF('Shipment Control'!$C$5:$C$304,A16,'Shipment Control'!$I$5:$I$304)) | R16: =IF(A16="","",SUMIF('Shipment Control'!$C$5:$C$304,A16,'Shipment Control'!$J$5:$J$304)) | S16: =IF(A16="","",Q16+R16-D16) | T16: =IF('FGPO Master'!A10="","",'FGPO Master'!I10) | U16: =IF(A16="","",IF(COUNTIF('Open Issues'!$D$5:$D$304,A16)>0,"Yellow","Green")) | V16: =IF('FGPO Master'!A10="","",'FGPO Master'!U10)
A17: =IF('FGPO Master'!A11="","",IF('FGPO Master'!D11="FGPO Pending","FGPO Pending",'FGPO Master'!B11)) | B17: =IF('FGPO Master'!A11="","",'FGPO Master'!F11) | C17: =IF('FGPO Master'!A11="","",'FGPO Master'!G11) | D17: =IF('FGPO Master'!A11="","",'FGPO Master'!H11) | E17: =IF(A17="","",IF(SUMIF('Fabric Inventory'!$C$5:$C$304,A17,'Fabric Inventory'!$O$5:$O$304)>0,"Shortage",IF(SUMIF('Fabric Inventory'!$C$5:$C$304,A17,'Fabric Inventory'!$H$5:$H$304)>0,"Approved","Pending"))) | F17: =IF(A17="","",IF(SUMIF('Trims Control'!$B$5:$B$304,A17,'Trims Control'!$R$5:$R$304)>0,"Shortage",IF(COUNTIFS('Trims Control'!$B$5:$B$304,A17,'Trims Control'!$V$5:$V$304,"Ready")>0,"Ready","Pending"))) | G17: =IF(A17="","",IFERROR(INDEX('PP Sample'!$V$5:$V$304,MATCH(A17,'PP Sample'!$B$5:$B$304,0)),"Pending")) | H17: =IF(A17="","",IFERROR(INDEX('Production Readiness'!$S$5:$S$304,MATCH(A17,'Production Readiness'!$C$5:$C$304,0)),"Pending")) | I17: =IF(A17="","",IFERROR(INDEX('Cutting Release'!$P$5:$P$304,MATCH(A17,'Cutting Release'!$C$5:$C$304,0)),"Pending")) | J17: =IF(A17="","",SUMIF('Cutting Control'!$C$5:$C$304,A17,'Cutting Control'!$K$5:$K$304)) | K17: =IF(A17="","",IFERROR(INDEX('TOP Sample'!$W$5:$W$304,MATCH(A17,'TOP Sample'!$B$5:$B$304,0)),"Pending")) | L17: =IF(A17="","",SUMIF('Sewing Production'!$E$5:$E$304,A17,'Sewing Production'!$L$5:$L$304)) | M17: =IF(A17="","",IFERROR(INDEX('Inline Quality'!$S$5:$S$304,MATCH(A17,'Inline Quality'!$E$5:$E$304,0)),"Pending")) | N17: =IF(A17="","",IFERROR(INDEX('Final Inspection'!$U$5:$U$304,MATCH(A17,'Final Inspection'!$C$5:$C$304,0)),"Pending")) | O17: =IF(A17="","",SUMIF('Packing Control'!$C$5:$C$304,A17,'Packing Control'!$K$5:$K$304)) | P17: =IF(A17="","",SUMIF('Finished Goods'!$C$5:$C$304,A17,'Finished Goods'!$J$5:$J$304)) | Q17: =IF(A17="","",SUMIF('Shipment Control'!$C$5:$C$304,A17,'Shipment Control'!$I$5:$I$304)) | R17: =IF(A17="","",SUMIF('Shipment Control'!$C$5:$C$304,A17,'Shipment Control'!$J$5:$J$304)) | S17: =IF(A17="","",Q17+R17-D17) | T17: =IF('FGPO Master'!A11="","",'FGPO Master'!I11) | U17: =IF(A17="","",IF(COUNTIF('Open Issues'!$D$5:$D$304,A17)>0,"Yellow","Green")) | V17: =IF('FGPO Master'!A11="","",'FGPO Master'!U11)
A18: =IF('FGPO Master'!A12="","",IF('FGPO Master'!D12="FGPO Pending","FGPO Pending",'FGPO Master'!B12)) | B18: =IF('FGPO Master'!A12="","",'FGPO Master'!F12) | C18: =IF('FGPO Master'!A12="","",'FGPO Master'!G12) | D18: =IF('FGPO Master'!A12="","",'FGPO Master'!H12) | E18: =IF(A18="","",IF(SUMIF('Fabric Inventory'!$C$5:$C$304,A18,'Fabric Inventory'!$O$5:$O$304)>0,"Shortage",IF(SUMIF('Fabric Inventory'!$C$5:$C$304,A18,'Fabric Inventory'!$H$5:$H$304)>0,"Approved","Pending"))) | F18: =IF(A18="","",IF(SUMIF('Trims Control'!$B$5:$B$304,A18,'Trims Control'!$R$5:$R$304)>0,"Shortage",IF(COUNTIFS('Trims Control'!$B$5:$B$304,A18,'Trims Control'!$V$5:$V$304,"Ready")>0,"Ready","Pending"))) | G18: =IF(A18="","",IFERROR(INDEX('PP Sample'!$V$5:$V$304,MATCH(A18,'PP Sample'!$B$5:$B$304,0)),"Pending")) | H18: =IF(A18="","",IFERROR(INDEX('Production Readiness'!$S$5:$S$304,MATCH(A18,'Production Readiness'!$C$5:$C$304,0)),"Pending")) | I18: =IF(A18="","",IFERROR(INDEX('Cutting Release'!$P$5:$P$304,MATCH(A18,'Cutting Release'!$C$5:$C$304,0)),"Pending")) | J18: =IF(A18="","",SUMIF('Cutting Control'!$C$5:$C$304,A18,'Cutting Control'!$K$5:$K$304)) | K18: =IF(A18="","",IFERROR(INDEX('TOP Sample'!$W$5:$W$304,MATCH(A18,'TOP Sample'!$B$5:$B$304,0)),"Pending")) | L18: =IF(A18="","",SUMIF('Sewing Production'!$E$5:$E$304,A18,'Sewing Production'!$L$5:$L$304)) | M18: =IF(A18="","",IFERROR(INDEX('Inline Quality'!$S$5:$S$304,MATCH(A18,'Inline Quality'!$E$5:$E$304,0)),"Pending")) | N18: =IF(A18="","",IFERROR(INDEX('Final Inspection'!$U$5:$U$304,MATCH(A18,'Final Inspection'!$C$5:$C$304,0)),"Pending")) | O18: =IF(A18="","",SUMIF('Packing Control'!$C$5:$C$304,A18,'Packing Control'!$K$5:$K$304)) | P18: =IF(A18="","",SUMIF('Finished Goods'!$C$5:$C$304,A18,'Finished Goods'!$J$5:$J$304)) | Q18: =IF(A18="","",SUMIF('Shipment Control'!$C$5:$C$304,A18,'Shipment Control'!$I$5:$I$304)) | R18: =IF(A18="","",SUMIF('Shipment Control'!$C$5:$C$304,A18,'Shipment Control'!$J$5:$J$304)) | S18: =IF(A18="","",Q18+R18-D18) | T18: =IF('FGPO Master'!A12="","",'FGPO Master'!I12) | U18: =IF(A18="","",IF(COUNTIF('Open Issues'!$D$5:$D$304,A18)>0,"Yellow","Green")) | V18: =IF('FGPO Master'!A12="","",'FGPO Master'!U12)
A19: =IF('FGPO Master'!A13="","",IF('FGPO Master'!D13="FGPO Pending","FGPO Pending",'FGPO Master'!B13)) | B19: =IF('FGPO Master'!A13="","",'FGPO Master'!F13) | C19: =IF('FGPO Master'!A13="","",'FGPO Master'!G13) | D19: =IF('FGPO Master'!A13="","",'FGPO Master'!H13) | E19: =IF(A19="","",IF(SUMIF('Fabric Inventory'!$C$5:$C$304,A19,'Fabric Inventory'!$O$5:$O$304)>0,"Shortage",IF(SUMIF('Fabric Inventory'!$C$5:$C$304,A19,'Fabric Inventory'!$H$5:$H$304)>0,"Approved","Pending"))) | F19: =IF(A19="","",IF(SUMIF('Trims Control'!$B$5:$B$304,A19,'Trims Control'!$R$5:$R$304)>0,"Shortage",IF(COUNTIFS('Trims Control'!$B$5:$B$304,A19,'Trims Control'!$V$5:$V$304,"Ready")>0,"Ready","Pending"))) | G19: =IF(A19="","",IFERROR(INDEX('PP Sample'!$V$5:$V$304,MATCH(A19,'PP Sample'!$B$5:$B$304,0)),"Pending")) | H19: =IF(A19="","",IFERROR(INDEX('Production Readiness'!$S$5:$S$304,MATCH(A19,'Production Readiness'!$C$5:$C$304,0)),"Pending")) | I19: =IF(A19="","",IFERROR(INDEX('Cutting Release'!$P$5:$P$304,MATCH(A19,'Cutting Release'!$C$5:$C$304,0)),"Pending")) | J19: =IF(A19="","",SUMIF('Cutting Control'!$C$5:$C$304,A19,'Cutting Control'!$K$5:$K$304)) | K19: =IF(A19="","",IFERROR(INDEX('TOP Sample'!$W$5:$W$304,MATCH(A19,'TOP Sample'!$B$5:$B$304,0)),"Pending")) | L19: =IF(A19="","",SUMIF('Sewing Production'!$E$5:$E$304,A19,'Sewing Production'!$L$5:$L$304)) | M19: =IF(A19="","",IFERROR(INDEX('Inline Quality'!$S$5:$S$304,MATCH(A19,'Inline Quality'!$E$5:$E$304,0)),"Pending")) | N19: =IF(A19="","",IFERROR(INDEX('Final Inspection'!$U$5:$U$304,MATCH(A19,'Final Inspection'!$C$5:$C$304,0)),"Pending")) | O19: =IF(A19="","",SUMIF('Packing Control'!$C$5:$C$304,A19,'Packing Control'!$K$5:$K$304)) | P19: =IF(A19="","",SUMIF('Finished Goods'!$C$5:$C$304,A19,'Finished Goods'!$J$5:$J$304)) | Q19: =IF(A19="","",SUMIF('Shipment Control'!$C$5:$C$304,A19,'Shipment Control'!$I$5:$I$304)) | R19: =IF(A19="","",SUMIF('Shipment Control'!$C$5:$C$304,A19,'Shipment Control'!$J$5:$J$304)) | S19: =IF(A19="","",Q19+R19-D19) | T19: =IF('FGPO Master'!A13="","",'FGPO Master'!I13) | U19: =IF(A19="","",IF(COUNTIF('Open Issues'!$D$5:$D$304,A19)>0,"Yellow","Green")) | V19: =IF('FGPO Master'!A13="","",'FGPO Master'!U13)
A20: =IF('FGPO Master'!A14="","",IF('FGPO Master'!D14="FGPO Pending","FGPO Pending",'FGPO Master'!B14)) | B20: =IF('FGPO Master'!A14="","",'FGPO Master'!F14) | C20: =IF('FGPO Master'!A14="","",'FGPO Master'!G14) | D20: =IF('FGPO Master'!A14="","",'FGPO Master'!H14) | E20: =IF(A20="","",IF(SUMIF('Fabric Inventory'!$C$5:$C$304,A20,'Fabric Inventory'!$O$5:$O$304)>0,"Shortage",IF(SUMIF('Fabric Inventory'!$C$5:$C$304,A20,'Fabric Inventory'!$H$5:$H$304)>0,"Approved","Pending"))) | F20: =IF(A20="","",IF(SUMIF('Trims Control'!$B$5:$B$304,A20,'Trims Control'!$R$5:$R$304)>0,"Shortage",IF(COUNTIFS('Trims Control'!$B$5:$B$304,A20,'Trims Control'!$V$5:$V$304,"Ready")>0,"Ready","Pending"))) | G20: =IF(A20="","",IFERROR(INDEX('PP Sample'!$V$5:$V$304,MATCH(A20,'PP Sample'!$B$5:$B$304,0)),"Pending")) | H20: =IF(A20="","",IFERROR(INDEX('Production Readiness'!$S$5:$S$304,MATCH(A20,'Production Readiness'!$C$5:$C$304,0)),"Pending")) | I20: =IF(A20="","",IFERROR(INDEX('Cutting Release'!$P$5:$P$304,MATCH(A20,'Cutting Release'!$C$5:$C$304,0)),"Pending")) | J20: =IF(A20="","",SUMIF('Cutting Control'!$C$5:$C$304,A20,'Cutting Control'!$K$5:$K$304)) | K20: =IF(A20="","",IFERROR(INDEX('TOP Sample'!$W$5:$W$304,MATCH(A20,'TOP Sample'!$B$5:$B$304,0)),"Pending")) | L20: =IF(A20="","",SUMIF('Sewing Production'!$E$5:$E$304,A20,'Sewing Production'!$L$5:$L$304)) | M20: =IF(A20="","",IFERROR(INDEX('Inline Quality'!$S$5:$S$304,MATCH(A20,'Inline Quality'!$E$5:$E$304,0)),"Pending")) | N20: =IF(A20="","",IFERROR(INDEX('Final Inspection'!$U$5:$U$304,MATCH(A20,'Final Inspection'!$C$5:$C$304,0)),"Pending")) | O20: =IF(A20="","",SUMIF('Packing Control'!$C$5:$C$304,A20,'Packing Control'!$K$5:$K$304)) | P20: =IF(A20="","",SUMIF('Finished Goods'!$C$5:$C$304,A20,'Finished Goods'!$J$5:$J$304)) | Q20: =IF(A20="","",SUMIF('Shipment Control'!$C$5:$C$304,A20,'Shipment Control'!$I$5:$I$304)) | R20: =IF(A20="","",SUMIF('Shipment Control'!$C$5:$C$304,A20,'Shipment Control'!$J$5:$J$304)) | S20: =IF(A20="","",Q20+R20-D20) | T20: =IF('FGPO Master'!A14="","",'FGPO Master'!I14) | U20: =IF(A20="","",IF(COUNTIF('Open Issues'!$D$5:$D$304,A20)>0,"Yellow","Green")) | V20: =IF('FGPO Master'!A14="","",'FGPO Master'!U14)
A21: =IF('FGPO Master'!A15="","",IF('FGPO Master'!D15="FGPO Pending","FGPO Pending",'FGPO Master'!B15)) | B21: =IF('FGPO Master'!A15="","",'FGPO Master'!F15) | C21: =IF('FGPO Master'!A15="","",'FGPO Master'!G15) | D21: =IF('FGPO Master'!A15="","",'FGPO Master'!H15) | E21: =IF(A21="","",IF(SUMIF('Fabric Inventory'!$C$5:$C$304,A21,'Fabric Inventory'!$O$5:$O$304)>0,"Shortage",IF(SUMIF('Fabric Inventory'!$C$5:$C$304,A21,'Fabric Inventory'!$H$5:$H$304)>0,"Approved","Pending"))) | F21: =IF(A21="","",IF(SUMIF('Trims Control'!$B$5:$B$304,A21,'Trims Control'!$R$5:$R$304)>0,"Shortage",IF(COUNTIFS('Trims Control'!$B$5:$B$304,A21,'Trims Control'!$V$5:$V$304,"Ready")>0,"Ready","Pending"))) | G21: =IF(A21="","",IFERROR(INDEX('PP Sample'!$V$5:$V$304,MATCH(A21,'PP Sample'!$B$5:$B$304,0)),"Pending")) | H21: =IF(A21="","",IFERROR(INDEX('Production Readiness'!$S$5:$S$304,MATCH(A21,'Production Readiness'!$C$5:$C$304,0)),"Pending")) | I21: =IF(A21="","",IFERROR(INDEX('Cutting Release'!$P$5:$P$304,MATCH(A21,'Cutting Release'!$C$5:$C$304,0)),"Pending")) | J21: =IF(A21="","",SUMIF('Cutting Control'!$C$5:$C$304,A21,'Cutting Control'!$K$5:$K$304)) | K21: =IF(A21="","",IFERROR(INDEX('TOP Sample'!$W$5:$W$304,MATCH(A21,'TOP Sample'!$B$5:$B$304,0)),"Pending")) | L21: =IF(A21="","",SUMIF('Sewing Production'!$E$5:$E$304,A21,'Sewing Production'!$L$5:$L$304)) | M21: =IF(A21="","",IFERROR(INDEX('Inline Quality'!$S$5:$S$304,MATCH(A21,'Inline Quality'!$E$5:$E$304,0)),"Pending")) | N21: =IF(A21="","",IFERROR(INDEX('Final Inspection'!$U$5:$U$304,MATCH(A21,'Final Inspection'!$C$5:$C$304,0)),"Pending")) | O21: =IF(A21="","",SUMIF('Packing Control'!$C$5:$C$304,A21,'Packing Control'!$K$5:$K$304)) | P21: =IF(A21="","",SUMIF('Finished Goods'!$C$5:$C$304,A21,'Finished Goods'!$J$5:$J$304)) | Q21: =IF(A21="","",SUMIF('Shipment Control'!$C$5:$C$304,A21,'Shipment Control'!$I$5:$I$304)) | R21: =IF(A21="","",SUMIF('Shipment Control'!$C$5:$C$304,A21,'Shipment Control'!$J$5:$J$304)) | S21: =IF(A21="","",Q21+R21-D21) | T21: =IF('FGPO Master'!A15="","",'FGPO Master'!I15) | U21: =IF(A21="","",IF(COUNTIF('Open Issues'!$D$5:$D$304,A21)>0,"Yellow","Green")) | V21: =IF('FGPO Master'!A15="","",'FGPO Master'!U15)
A22: =IF('FGPO Master'!A16="","",IF('FGPO Master'!D16="FGPO Pending","FGPO Pending",'FGPO Master'!B16)) | B22: =IF('FGPO Master'!A16="","",'FGPO Master'!F16) | C22: =IF('FGPO Master'!A16="","",'FGPO Master'!G16) | D22: =IF('FGPO Master'!A16="","",'FGPO Master'!H16) | E22: =IF(A22="","",IF(SUMIF('Fabric Inventory'!$C$5:$C$304,A22,'Fabric Inventory'!$O$5:$O$304)>0,"Shortage",IF(SUMIF('Fabric Inventory'!$C$5:$C$304,A22,'Fabric Inventory'!$H$5:$H$304)>0,"Approved","Pending"))) | F22: =IF(A22="","",IF(SUMIF('Trims Control'!$B$5:$B$304,A22,'Trims Control'!$R$5:$R$304)>0,"Shortage",IF(COUNTIFS('Trims Control'!$B$5:$B$304,A22,'Trims Control'!$V$5:$V$304,"Ready")>0,"Ready","Pending"))) | G22: =IF(A22="","",IFERROR(INDEX('PP Sample'!$V$5:$V$304,MATCH(A22,'PP Sample'!$B$5:$B$304,0)),"Pending")) | H22: =IF(A22="","",IFERROR(INDEX('Production Readiness'!$S$5:$S$304,MATCH(A22,'Production Readiness'!$C$5:$C$304,0)),"Pending")) | I22: =IF(A22="","",IFERROR(INDEX('Cutting Release'!$P$5:$P$304,MATCH(A22,'Cutting Release'!$C$5:$C$304,0)),"Pending")) | J22: =IF(A22="","",SUMIF('Cutting Control'!$C$5:$C$304,A22,'Cutting Control'!$K$5:$K$304)) | K22: =IF(A22="","",IFERROR(INDEX('TOP Sample'!$W$5:$W$304,MATCH(A22,'TOP Sample'!$B$5:$B$304,0)),"Pending")) | L22: =IF(A22="","",SUMIF('Sewing Production'!$E$5:$E$304,A22,'Sewing Production'!$L$5:$L$304)) | M22: =IF(A22="","",IFERROR(INDEX('Inline Quality'!$S$5:$S$304,MATCH(A22,'Inline Quality'!$E$5:$E$304,0)),"Pending")) | N22: =IF(A22="","",IFERROR(INDEX('Final Inspection'!$U$5:$U$304,MATCH(A22,'Final Inspection'!$C$5:$C$304,0)),"Pending")) | O22: =IF(A22="","",SUMIF('Packing Control'!$C$5:$C$304,A22,'Packing Control'!$K$5:$K$304)) | P22: =IF(A22="","",SUMIF('Finished Goods'!$C$5:$C$304,A22,'Finished Goods'!$J$5:$J$304)) | Q22: =IF(A22="","",SUMIF('Shipment Control'!$C$5:$C$304,A22,'Shipment Control'!$I$5:$I$304)) | R22: =IF(A22="","",SUMIF('Shipment Control'!$C$5:$C$304,A22,'Shipment Control'!$J$5:$J$304)) | S22: =IF(A22="","",Q22+R22-D22) | T22: =IF('FGPO Master'!A16="","",'FGPO Master'!I16) | U22: =IF(A22="","",IF(COUNTIF('Open Issues'!$D$5:$D$304,A22)>0,"Yellow","Green")) | V22: =IF('FGPO Master'!A16="","",'FGPO Master'!U16)
... A210: =IF('FGPO Master'!A204="","",IF('FGPO Master'!D204="FGPO Pending","FGPO Pending",'FGPO Master'!B204)) | B210: =IF('FGPO Master'!A204="","",'FGPO Master'!F204) | C210: =IF('FGPO Master'!A204="","",'FGPO Master'!G204) | D210: =IF('FGPO Master'!A204="","",'FGPO Master'!H204) | E210: =IF(A210="","",IF(SUMIF('Fabric Inventory'!$C$5:$C$304,A210,'Fabric Inventory'!$O$5:$O$304)>0,"Shortage",IF(SUMIF('Fabric Inventory'!$C$5:$C$304,A210,'Fabric Inventory'!$H$5:$H$304)>0,"Approved","Pending"))) | F210: =IF(A210="","",IF(SUMIF('Trims Control'!$B$5:$B$304,A210,'Trims Control'!$R$5:$R$304)>0,"Shortage",IF(COUNTIFS('Trims Control'!$B$5:$B$304,A210,'Trims Control'!$V$5:$V$304,"Ready")>0,"Ready","Pending"))) | G210: =IF(A210="","",IFERROR(INDEX('PP Sample'!$V$5:$V$304,MATCH(A210,'PP Sample'!$B$5:$B$304,0)),"Pending")) | H210: =IF(A210="","",IFERROR(INDEX('Production Readiness'!$S$5:$S$304,MATCH(A210,'Production Readiness'!$C$5:$C$304,0)),"Pending")) | I210: =IF(A210="","",IFERROR(INDEX('Cutting Release'!$P$5:$P$304,MATCH(A210,'Cutting Release'!$C$5:$C$304,0)),"Pending")) | J210: =IF(A210="","",SUMIF('Cutting Control'!$C$5:$C$304,A210,'Cutting Control'!$K$5:$K$304)) | K210: =IF(A210="","",IFERROR(INDEX('TOP Sample'!$W$5:$W$304,MATCH(A210,'TOP Sample'!$B$5:$B$304,0)),"Pending")) | L210: =IF(A210="","",SUMIF('Sewing Production'!$E$5:$E$304,A210,'Sewing Production'!$L$5:$L$304)) | M210: =IF(A210="","",IFERROR(INDEX('Inline Quality'!$S$5:$S$304,MATCH(A210,'Inline Quality'!$E$5:$E$304,0)),"Pending")) | N210: =IF(A210="","",IFERROR(INDEX('Final Inspection'!$U$5:$U$304,MATCH(A210,'Final Inspection'!$C$5:$C$304,0)),"Pending")) | O210: =IF(A210="","",SUMIF('Packing Control'!$C$5:$C$304,A210,'Packing Control'!$K$5:$K$304)) | P210: =IF(A210="","",SUMIF('Finished Goods'!$C$5:$C$304,A210,'Finished Goods'!$J$5:$J$304)) | Q210: =IF(A210="","",SUMIF('Shipment Control'!$C$5:$C$304,A210,'Shipment Control'!$I$5:$I$304)) | R210: =IF(A210="","",SUMIF('Shipment Control'!$C$5:$C$304,A210,'Shipment Control'!$J$5:$J$304)) | S210: =IF(A210="","",Q210+R210-D210) | T210: =IF('FGPO Master'!A204="","",'FGPO Master'!I204) | U210: =IF(A210="","",IF(COUNTIF('Open Issues'!$D$5:$D$304,A210)>0,"Yellow","Green")) | V210: =IF('FGPO Master'!A204="","",'FGPO Master'!U204)

Sheet Fabric Dashboard
A1: TEXNICA TPCS 1.0 — FGPO & FABRIC CONTROL DASHBOARD
A2: Automatic summary by FGPO. Enter order and operational data in the detailed modules; do not type over dashboard formulas.
A4: Total FGPO | E4: Total Order Qty | I4: Fabric In Transit | M4: Fabric Received | Q4: Fabric Approved | U4: Open Shortage
A5: =COUNTA('FGPO Master'!B5:B304) -> 0 | E5: =SUM('FGPO Master'!H5:H304) -> 0 | I5: =SUM('Fabric Shipment'!R5:R304) -> 0 | M5: =SUM('Fabric Receiving'!H5:H304) -> 0 | Q5: =SUM('Fabric Inventory'!H5:H304) -> 0 | U5: =SUM('Fabric Inventory'!O5:O304) -> 0
A10: Customer | B10: FGPO | C10: Status | D10: Style | E10: Color | F10: Order Qty | G10: Shipment Variance | H10: Fabric Required | I10: Fabric Ordered | J10: Mill Produced | K10: Mill Test | L10: Fabric Exported | M10: Fabric In Transit | N10: Texnica Received | O10: Receiving Variance | P10: Four-Point | Q10: Internal Test | R10: Shade Match | S10: Fabric Approved | T10: Reserved | U10: Issued to Cutting | V10: Available | W10: Shortage
A11: =IF('FGPO Master'!A5="","",'FGPO Master'!E5) | B11: =IF('FGPO Master'!A5="","",IF('FGPO Master'!D5="FGPO Pending","FGPO Pending",'FGPO Master'!B5)) | C11: =IF('FGPO Master'!A5="","",'FGPO Master'!D5) | D11: =IF('FGPO Master'!A5="","",'FGPO Master'!F5) | E11: =IF('FGPO Master'!A5="","",'FGPO Master'!G5) | F11: =IF('FGPO Master'!A5="","",'FGPO Master'!H5) | G11: =IF('FGPO Master'!A5="","",'FGPO Master'!M5) | H11: =IF(B11="","",SUMIF('Fabric Requirement'!$B$5:$B$304,B11,'Fabric Requirement'!$M$5:$M$304)+SUMIF('Fabric Requirement'!$B$5:$B$304,B11,'Fabric Requirement'!$O$5:$O$304)) | I11: =IF(B11="","",SUMIF('Fabric PO'!$B$5:$B$304,B11,'Fabric PO'!$H$5:$H$304)) | J11: =IF(B11="","",SUMIF('Mill Production'!$C$5:$C$304,B11,'Mill Production'!$I$5:$I$304)) | K11: =IF(B11="","",IF(COUNTIF('Mill Test'!$C$5:$C$304,B11)=0,"Pending",IF(COUNTIFS('Mill Test'!$C$5:$C$304,B11,'Mill Test'!$T$5:$T$304,"Failed")>0,"Failed","Passed"))) | L11: =IF(B11="","",SUMIF('Fabric Shipment'!$C$5:$C$304,B11,'Fabric Shipment'!$G$5:$G$304)) | M11: =IF(B11="","",SUMIF('Fabric Shipment'!$C$5:$C$304,B11,'Fabric Shipment'!$R$5:$R$304)) | N11: =IF(B11="","",SUMIF('Fabric Receiving'!$E$5:$E$304,B11,'Fabric Receiving'!$H$5:$H$304)) | O11: =IF(B11="","",SUMIF('Fabric Receiving'!$E$5:$E$304,B11,'Fabric Receiving'!$I$5:$I$304)) | P11: =IF(B11="","",IF(COUNTIF('Four-Point'!$E$5:$E$304,B11)=0,"Pending",IF(COUNTIFS('Four-Point'!$E$5:$E$304,B11,'Four-Point'!$T$5:$T$304,"Failed")>0,"Failed","Passed"))) | Q11: =IF(B11="","",IF(COUNTIF('Internal Test'!$D$5:$D$304,B11)=0,"Pending",IF(COUNTIFS('Internal Test'!$D$5:$D$304,B11,'Internal Test'!$AA$5:$AA$304,"Failed")>0,"Failed","Passed"))) | R11: =IF(B11="","",IF(COUNTIF('Shade Match'!$C$5:$C$304,B11)=0,"Pending",IF(COUNTIFS('Shade Match'!$C$5:$C$304,B11,'Shade Match'!$Q$5:$Q$304,"Failed")>0,"Failed","Approved"))) | S11: =IF(B11="","",SUMIF('Fabric Inventory'!$C$5:$C$304,B11,'Fabric Inventory'!$H$5:$H$304)) | T11: =IF(B11="","",SUMIF('Fabric Inventory'!$C$5:$C$304,B11,'Fabric Inventory'!$K$5:$K$304)) | U11: =IF(B11="","",SUMIF('Fabric Inventory'!$C$5:$C$304,B11,'Fabric Inventory'!$L$5:$L$304)) | V11: =IF(B11="","",SUMIF('Fabric Inventory'!$C$5:$C$304,B11,'Fabric Inventory'!$N$5:$N$304)) | W11: =IF(B11="","",SUMIF('Fabric Inventory'!$C$5:$C$304,B11,'Fabric Inventory'!$O$5:$O$304))
A12: =IF('FGPO Master'!A6="","",'FGPO Master'!E6) | B12: =IF('FGPO Master'!A6="","",IF('FGPO Master'!D6="FGPO Pending","FGPO Pending",'FGPO Master'!B6)) | C12: =IF('FGPO Master'!A6="","",'FGPO Master'!D6) | D12: =IF('FGPO Master'!A6="","",'FGPO Master'!F6) | E12: =IF('FGPO Master'!A6="","",'FGPO Master'!G6) | F12: =IF('FGPO Master'!A6="","",'FGPO Master'!H6) | G12: =IF('FGPO Master'!A6="","",'FGPO Master'!M6) | H12: =IF(B12="","",SUMIF('Fabric Requirement'!$B$5:$B$304,B12,'Fabric Requirement'!$M$5:$M$304)+SUMIF('Fabric Requirement'!$B$5:$B$304,B12,'Fabric Requirement'!$O$5:$O$304)) | I12: =IF(B12="","",SUMIF('Fabric PO'!$B$5:$B$304,B12,'Fabric PO'!$H$5:$H$304)) | J12: =IF(B12="","",SUMIF('Mill Production'!$C$5:$C$304,B12,'Mill Production'!$I$5:$I$304)) | K12: =IF(B12="","",IF(COUNTIF('Mill Test'!$C$5:$C$304,B12)=0,"Pending",IF(COUNTIFS('Mill Test'!$C$5:$C$304,B12,'Mill Test'!$T$5:$T$304,"Failed")>0,"Failed","Passed"))) | L12: =IF(B12="","",SUMIF('Fabric Shipment'!$C$5:$C$304,B12,'Fabric Shipment'!$G$5:$G$304)) | M12: =IF(B12="","",SUMIF('Fabric Shipment'!$C$5:$C$304,B12,'Fabric Shipment'!$R$5:$R$304)) | N12: =IF(B12="","",SUMIF('Fabric Receiving'!$E$5:$E$304,B12,'Fabric Receiving'!$H$5:$H$304)) | O12: =IF(B12="","",SUMIF('Fabric Receiving'!$E$5:$E$304,B12,'Fabric Receiving'!$I$5:$I$304)) | P12: =IF(B12="","",IF(COUNTIF('Four-Point'!$E$5:$E$304,B12)=0,"Pending",IF(COUNTIFS('Four-Point'!$E$5:$E$304,B12,'Four-Point'!$T$5:$T$304,"Failed")>0,"Failed","Passed"))) | Q12: =IF(B12="","",IF(COUNTIF('Internal Test'!$D$5:$D$304,B12)=0,"Pending",IF(COUNTIFS('Internal Test'!$D$5:$D$304,B12,'Internal Test'!$AA$5:$AA$304,"Failed")>0,"Failed","Passed"))) | R12: =IF(B12="","",IF(COUNTIF('Shade Match'!$C$5:$C$304,B12)=0,"Pending",IF(COUNTIFS('Shade Match'!$C$5:$C$304,B12,'Shade Match'!$Q$5:$Q$304,"Failed")>0,"Failed","Approved"))) | S12: =IF(B12="","",SUMIF('Fabric Inventory'!$C$5:$C$304,B12,'Fabric Inventory'!$H$5:$H$304)) | T12: =IF(B12="","",SUMIF('Fabric Inventory'!$C$5:$C$304,B12,'Fabric Inventory'!$K$5:$K$304)) | U12: =IF(B12="","",SUMIF('Fabric Inventory'!$C$5:$C$304,B12,'Fabric Inventory'!$L$5:$L$304)) | V12: =IF(B12="","",SUMIF('Fabric Inventory'!$C$5:$C$304,B12,'Fabric Inventory'!$N$5:$N$304)) | W12: =IF(B12="","",SUMIF('Fabric Inventory'!$C$5:$C$304,B12,'Fabric Inventory'!$O$5:$O$304))
A13: =IF('FGPO Master'!A7="","",'FGPO Master'!E7) | B13: =IF('FGPO Master'!A7="","",IF('FGPO Master'!D7="FGPO Pending","FGPO Pending",'FGPO Master'!B7)) | C13: =IF('FGPO Master'!A7="","",'FGPO Master'!D7) | D13: =IF('FGPO Master'!A7="","",'FGPO Master'!F7) | E13: =IF('FGPO Master'!A7="","",'FGPO Master'!G7) | F13: =IF('FGPO Master'!A7="","",'FGPO Master'!H7) | G13: =IF('FGPO Master'!A7="","",'FGPO Master'!M7) | H13: =IF(B13="","",SUMIF('Fabric Requirement'!$B$5:$B$304,B13,'Fabric Requirement'!$M$5:$M$304)+SUMIF('Fabric Requirement'!$B$5:$B$304,B13,'Fabric Requirement'!$O$5:$O$304)) | I13: =IF(B13="","",SUMIF('Fabric PO'!$B$5:$B$304,B13,'Fabric PO'!$H$5:$H$304)) | J13: =IF(B13="","",SUMIF('Mill Production'!$C$5:$C$304,B13,'Mill Production'!$I$5:$I$304)) | K13: =IF(B13="","",IF(COUNTIF('Mill Test'!$C$5:$C$304,B13)=0,"Pending",IF(COUNTIFS('Mill Test'!$C$5:$C$304,B13,'Mill Test'!$T$5:$T$304,"Failed")>0,"Failed","Passed"))) | L13: =IF(B13="","",SUMIF('Fabric Shipment'!$C$5:$C$304,B13,'Fabric Shipment'!$G$5:$G$304)) | M13: =IF(B13="","",SUMIF('Fabric Shipment'!$C$5:$C$304,B13,'Fabric Shipment'!$R$5:$R$304)) | N13: =IF(B13="","",SUMIF('Fabric Receiving'!$E$5:$E$304,B13,'Fabric Receiving'!$H$5:$H$304)) | O13: =IF(B13="","",SUMIF('Fabric Receiving'!$E$5:$E$304,B13,'Fabric Receiving'!$I$5:$I$304)) | P13: =IF(B13="","",IF(COUNTIF('Four-Point'!$E$5:$E$304,B13)=0,"Pending",IF(COUNTIFS('Four-Point'!$E$5:$E$304,B13,'Four-Point'!$T$5:$T$304,"Failed")>0,"Failed","Passed"))) | Q13: =IF(B13="","",IF(COUNTIF('Internal Test'!$D$5:$D$304,B13)=0,"Pending",IF(COUNTIFS('Internal Test'!$D$5:$D$304,B13,'Internal Test'!$AA$5:$AA$304,"Failed")>0,"Failed","Passed"))) | R13: =IF(B13="","",IF(COUNTIF('Shade Match'!$C$5:$C$304,B13)=0,"Pending",IF(COUNTIFS('Shade Match'!$C$5:$C$304,B13,'Shade Match'!$Q$5:$Q$304,"Failed")>0,"Failed","Approved"))) | S13: =IF(B13="","",SUMIF('Fabric Inventory'!$C$5:$C$304,B13,'Fabric Inventory'!$H$5:$H$304)) | T13: =IF(B13="","",SUMIF('Fabric Inventory'!$C$5:$C$304,B13,'Fabric Inventory'!$K$5:$K$304)) | U13: =IF(B13="","",SUMIF('Fabric Inventory'!$C$5:$C$304,B13,'Fabric Inventory'!$L$5:$L$304)) | V13: =IF(B13="","",SUMIF('Fabric Inventory'!$C$5:$C$304,B13,'Fabric Inventory'!$N$5:$N$304)) | W13: =IF(B13="","",SUMIF('Fabric Inventory'!$C$5:$C$304,B13,'Fabric Inventory'!$O$5:$O$304))
A14: =IF('FGPO Master'!A8="","",'FGPO Master'!E8) | B14: =IF('FGPO Master'!A8="","",IF('FGPO Master'!D8="FGPO Pending","FGPO Pending",'FGPO Master'!B8)) | C14: =IF('FGPO Master'!A8="","",'FGPO Master'!D8) | D14: =IF('FGPO Master'!A8="","",'FGPO Master'!F8) | E14: =IF('FGPO Master'!A8="","",'FGPO Master'!G8) | F14: =IF('FGPO Master'!A8="","",'FGPO Master'!H8) | G14: =IF('FGPO Master'!A8="","",'FGPO Master'!M8) | H14: =IF(B14="","",SUMIF('Fabric Requirement'!$B$5:$B$304,B14,'Fabric Requirement'!$M$5:$M$304)+SUMIF('Fabric Requirement'!$B$5:$B$304,B14,'Fabric Requirement'!$O$5:$O$304)) | I14: =IF(B14="","",SUMIF('Fabric PO'!$B$5:$B$304,B14,'Fabric PO'!$H$5:$H$304)) | J14: =IF(B14="","",SUMIF('Mill Production'!$C$5:$C$304,B14,'Mill Production'!$I$5:$I$304)) | K14: =IF(B14="","",IF(COUNTIF('Mill Test'!$C$5:$C$304,B14)=0,"Pending",IF(COUNTIFS('Mill Test'!$C$5:$C$304,B14,'Mill Test'!$T$5:$T$304,"Failed")>0,"Failed","Passed"))) | L14: =IF(B14="","",SUMIF('Fabric Shipment'!$C$5:$C$304,B14,'Fabric Shipment'!$G$5:$G$304)) | M14: =IF(B14="","",SUMIF('Fabric Shipment'!$C$5:$C$304,B14,'Fabric Shipment'!$R$5:$R$304)) | N14: =IF(B14="","",SUMIF('Fabric Receiving'!$E$5:$E$304,B14,'Fabric Receiving'!$H$5:$H$304)) | O14: =IF(B14="","",SUMIF('Fabric Receiving'!$E$5:$E$304,B14,'Fabric Receiving'!$I$5:$I$304)) | P14: =IF(B14="","",IF(COUNTIF('Four-Point'!$E$5:$E$304,B14)=0,"Pending",IF(COUNTIFS('Four-Point'!$E$5:$E$304,B14,'Four-Point'!$T$5:$T$304,"Failed")>0,"Failed","Passed"))) | Q14: =IF(B14="","",IF(COUNTIF('Internal Test'!$D$5:$D$304,B14)=0,"Pending",IF(COUNTIFS('Internal Test'!$D$5:$D$304,B14,'Internal Test'!$AA$5:$AA$304,"Failed")>0,"Failed","Passed"))) | R14: =IF(B14="","",IF(COUNTIF('Shade Match'!$C$5:$C$304,B14)=0,"Pending",IF(COUNTIFS('Shade Match'!$C$5:$C$304,B14,'Shade Match'!$Q$5:$Q$304,"Failed")>0,"Failed","Approved"))) | S14: =IF(B14="","",SUMIF('Fabric Inventory'!$C$5:$C$304,B14,'Fabric Inventory'!$H$5:$H$304)) | T14: =IF(B14="","",SUMIF('Fabric Inventory'!$C$5:$C$304,B14,'Fabric Inventory'!$K$5:$K$304)) | U14: =IF(B14="","",SUMIF('Fabric Inventory'!$C$5:$C$304,B14,'Fabric Inventory'!$L$5:$L$304)) | V14: =IF(B14="","",SUMIF('Fabric Inventory'!$C$5:$C$304,B14,'Fabric Inventory'!$N$5:$N$304)) | W14: =IF(B14="","",SUMIF('Fabric Inventory'!$C$5:$C$304,B14,'Fabric Inventory'!$O$5:$O$304))
A15: =IF('FGPO Master'!A9="","",'FGPO Master'!E9) | B15: =IF('FGPO Master'!A9="","",IF('FGPO Master'!D9="FGPO Pending","FGPO Pending",'FGPO Master'!B9)) | C15: =IF('FGPO Master'!A9="","",'FGPO Master'!D9) | D15: =IF('FGPO Master'!A9="","",'FGPO Master'!F9) | E15: =IF('FGPO Master'!A9="","",'FGPO Master'!G9) | F15: =IF('FGPO Master'!A9="","",'FGPO Master'!H9) | G15: =IF('FGPO Master'!A9="","",'FGPO Master'!M9) | H15: =IF(B15="","",SUMIF('Fabric Requirement'!$B$5:$B$304,B15,'Fabric Requirement'!$M$5:$M$304)+SUMIF('Fabric Requirement'!$B$5:$B$304,B15,'Fabric Requirement'!$O$5:$O$304)) | I15: =IF(B15="","",SUMIF('Fabric PO'!$B$5:$B$304,B15,'Fabric PO'!$H$5:$H$304)) | J15: =IF(B15="","",SUMIF('Mill Production'!$C$5:$C$304,B15,'Mill Production'!$I$5:$I$304)) | K15: =IF(B15="","",IF(COUNTIF('Mill Test'!$C$5:$C$304,B15)=0,"Pending",IF(COUNTIFS('Mill Test'!$C$5:$C$304,B15,'Mill Test'!$T$5:$T$304,"Failed")>0,"Failed","Passed"))) | L15: =IF(B15="","",SUMIF('Fabric Shipment'!$C$5:$C$304,B15,'Fabric Shipment'!$G$5:$G$304)) | M15: =IF(B15="","",SUMIF('Fabric Shipment'!$C$5:$C$304,B15,'Fabric Shipment'!$R$5:$R$304)) | N15: =IF(B15="","",SUMIF('Fabric Receiving'!$E$5:$E$304,B15,'Fabric Receiving'!$H$5:$H$304)) | O15: =IF(B15="","",SUMIF('Fabric Receiving'!$E$5:$E$304,B15,'Fabric Receiving'!$I$5:$I$304)) | P15: =IF(B15="","",IF(COUNTIF('Four-Point'!$E$5:$E$304,B15)=0,"Pending",IF(COUNTIFS('Four-Point'!$E$5:$E$304,B15,'Four-Point'!$T$5:$T$304,"Failed")>0,"Failed","Passed"))) | Q15: =IF(B15="","",IF(COUNTIF('Internal Test'!$D$5:$D$304,B15)=0,"Pending",IF(COUNTIFS('Internal Test'!$D$5:$D$304,B15,'Internal Test'!$AA$5:$AA$304,"Failed")>0,"Failed","Passed"))) | R15: =IF(B15="","",IF(COUNTIF('Shade Match'!$C$5:$C$304,B15)=0,"Pending",IF(COUNTIFS('Shade Match'!$C$5:$C$304,B15,'Shade Match'!$Q$5:$Q$304,"Failed")>0,"Failed","Approved"))) | S15: =IF(B15="","",SUMIF('Fabric Inventory'!$C$5:$C$304,B15,'Fabric Inventory'!$H$5:$H$304)) | T15: =IF(B15="","",SUMIF('Fabric Inventory'!$C$5:$C$304,B15,'Fabric Inventory'!$K$5:$K$304)) | U15: =IF(B15="","",SUMIF('Fabric Inventory'!$C$5:$C$304,B15,'Fabric Inventory'!$L$5:$L$304)) | V15: =IF(B15="","",SUMIF('Fabric Inventory'!$C$5:$C$304,B15,'Fabric Inventory'!$N$5:$N$304)) | W15: =IF(B15="","",SUMIF('Fabric Inventory'!$C$5:$C$304,B15,'Fabric Inventory'!$O$5:$O$304))
A16: =IF('FGPO Master'!A10="","",'FGPO Master'!E10) | B16: =IF('FGPO Master'!A10="","",IF('FGPO Master'!D10="FGPO Pending","FGPO Pending",'FGPO Master'!B10)) | C16: =IF('FGPO Master'!A10="","",'FGPO Master'!D10) | D16: =IF('FGPO Master'!A10="","",'FGPO Master'!F10) | E16: =IF('FGPO Master'!A10="","",'FGPO Master'!G10) | F16: =IF('FGPO Master'!A10="","",'FGPO Master'!H10) | G16: =IF('FGPO Master'!A10="","",'FGPO Master'!M10) | H16: =IF(B16="","",SUMIF('Fabric Requirement'!$B$5:$B$304,B16,'Fabric Requirement'!$M$5:$M$304)+SUMIF('Fabric Requirement'!$B$5:$B$304,B16,'Fabric Requirement'!$O$5:$O$304)) | I16: =IF(B16="","",SUMIF('Fabric PO'!$B$5:$B$304,B16,'Fabric PO'!$H$5:$H$304)) | J16: =IF(B16="","",SUMIF('Mill Production'!$C$5:$C$304,B16,'Mill Production'!$I$5:$I$304)) | K16: =IF(B16="","",IF(COUNTIF('Mill Test'!$C$5:$C$304,B16)=0,"Pending",IF(COUNTIFS('Mill Test'!$C$5:$C$304,B16,'Mill Test'!$T$5:$T$304,"Failed")>0,"Failed","Passed"))) | L16: =IF(B16="","",SUMIF('Fabric Shipment'!$C$5:$C$304,B16,'Fabric Shipment'!$G$5:$G$304)) | M16: =IF(B16="","",SUMIF('Fabric Shipment'!$C$5:$C$304,B16,'Fabric Shipment'!$R$5:$R$304)) | N16: =IF(B16="","",SUMIF('Fabric Receiving'!$E$5:$E$304,B16,'Fabric Receiving'!$H$5:$H$304)) | O16: =IF(B16="","",SUMIF('Fabric Receiving'!$E$5:$E$304,B16,'Fabric Receiving'!$I$5:$I$304)) | P16: =IF(B16="","",IF(COUNTIF('Four-Point'!$E$5:$E$304,B16)=0,"Pending",IF(COUNTIFS('Four-Point'!$E$5:$E$304,B16,'Four-Point'!$T$5:$T$304,"Failed")>0,"Failed","Passed"))) | Q16: =IF(B16="","",IF(COUNTIF('Internal Test'!$D$5:$D$304,B16)=0,"Pending",IF(COUNTIFS('Internal Test'!$D$5:$D$304,B16,'Internal Test'!$AA$5:$AA$304,"Failed")>0,"Failed","Passed"))) | R16: =IF(B16="","",IF(COUNTIF('Shade Match'!$C$5:$C$304,B16)=0,"Pending",IF(COUNTIFS('Shade Match'!$C$5:$C$304,B16,'Shade Match'!$Q$5:$Q$304,"Failed")>0,"Failed","Approved"))) | S16: =IF(B16="","",SUMIF('Fabric Inventory'!$C$5:$C$304,B16,'Fabric Inventory'!$H$5:$H$304)) | T16: =IF(B16="","",SUMIF('Fabric Inventory'!$C$5:$C$304,B16,'Fabric Inventory'!$K$5:$K$304)) | U16: =IF(B16="","",SUMIF('Fabric Inventory'!$C$5:$C$304,B16,'Fabric Inventory'!$L$5:$L$304)) | V16: =IF(B16="","",SUMIF('Fabric Inventory'!$C$5:$C$304,B16,'Fabric Inventory'!$N$5:$N$304)) | W16: =IF(B16="","",SUMIF('Fabric Inventory'!$C$5:$C$304,B16,'Fabric Inventory'!$O$5:$O$304))
A17: =IF('FGPO Master'!A11="","",'FGPO Master'!E11) | B17: =IF('FGPO Master'!A11="","",IF('FGPO Master'!D11="FGPO Pending","FGPO Pending",'FGPO Master'!B11)) | C17: =IF('FGPO Master'!A11="","",'FGPO Master'!D11) | D17: =IF('FGPO Master'!A11="","",'FGPO Master'!F11) | E17: =IF('FGPO Master'!A11="","",'FGPO Master'!G11) | F17: =IF('FGPO Master'!A11="","",'FGPO Master'!H11) | G17: =IF('FGPO Master'!A11="","",'FGPO Master'!M11) | H17: =IF(B17="","",SUMIF('Fabric Requirement'!$B$5:$B$304,B17,'Fabric Requirement'!$M$5:$M$304)+SUMIF('Fabric Requirement'!$B$5:$B$304,B17,'Fabric Requirement'!$O$5:$O$304)) | I17: =IF(B17="","",SUMIF('Fabric PO'!$B$5:$B$304,B17,'Fabric PO'!$H$5:$H$304)) | J17: =IF(B17="","",SUMIF('Mill Production'!$C$5:$C$304,B17,'Mill Production'!$I$5:$I$304)) | K17: =IF(B17="","",IF(COUNTIF('Mill Test'!$C$5:$C$304,B17)=0,"Pending",IF(COUNTIFS('Mill Test'!$C$5:$C$304,B17,'Mill Test'!$T$5:$T$304,"Failed")>0,"Failed","Passed"))) | L17: =IF(B17="","",SUMIF('Fabric Shipment'!$C$5:$C$304,B17,'Fabric Shipment'!$G$5:$G$304)) | M17: =IF(B17="","",SUMIF('Fabric Shipment'!$C$5:$C$304,B17,'Fabric Shipment'!$R$5:$R$304)) | N17: =IF(B17="","",SUMIF('Fabric Receiving'!$E$5:$E$304,B17,'Fabric Receiving'!$H$5:$H$304)) | O17: =IF(B17="","",SUMIF('Fabric Receiving'!$E$5:$E$304,B17,'Fabric Receiving'!$I$5:$I$304)) | P17: =IF(B17="","",IF(COUNTIF('Four-Point'!$E$5:$E$304,B17)=0,"Pending",IF(COUNTIFS('Four-Point'!$E$5:$E$304,B17,'Four-Point'!$T$5:$T$304,"Failed")>0,"Failed","Passed"))) | Q17: =IF(B17="","",IF(COUNTIF('Internal Test'!$D$5:$D$304,B17)=0,"Pending",IF(COUNTIFS('Internal Test'!$D$5:$D$304,B17,'Internal Test'!$AA$5:$AA$304,"Failed")>0,"Failed","Passed"))) | R17: =IF(B17="","",IF(COUNTIF('Shade Match'!$C$5:$C$304,B17)=0,"Pending",IF(COUNTIFS('Shade Match'!$C$5:$C$304,B17,'Shade Match'!$Q$5:$Q$304,"Failed")>0,"Failed","Approved"))) | S17: =IF(B17="","",SUMIF('Fabric Inventory'!$C$5:$C$304,B17,'Fabric Inventory'!$H$5:$H$304)) | T17: =IF(B17="","",SUMIF('Fabric Inventory'!$C$5:$C$304,B17,'Fabric Inventory'!$K$5:$K$304)) | U17: =IF(B17="","",SUMIF('Fabric Inventory'!$C$5:$C$304,B17,'Fabric Inventory'!$L$5:$L$304)) | V17: =IF(B17="","",SUMIF('Fabric Inventory'!$C$5:$C$304,B17,'Fabric Inventory'!$N$5:$N$304)) | W17: =IF(B17="","",SUMIF('Fabric Inventory'!$C$5:$C$304,B17,'Fabric Inventory'!$O$5:$O$304))
A18: =IF('FGPO Master'!A12="","",'FGPO Master'!E12) | B18: =IF('FGPO Master'!A12="","",IF('FGPO Master'!D12="FGPO Pending","FGPO Pending",'FGPO Master'!B12)) | C18: =IF('FGPO Master'!A12="","",'FGPO Master'!D12) | D18: =IF('FGPO Master'!A12="","",'FGPO Master'!F12) | E18: =IF('FGPO Master'!A12="","",'FGPO Master'!G12) | F18: =IF('FGPO Master'!A12="","",'FGPO Master'!H12) | G18: =IF('FGPO Master'!A12="","",'FGPO Master'!M12) | H18: =IF(B18="","",SUMIF('Fabric Requirement'!$B$5:$B$304,B18,'Fabric Requirement'!$M$5:$M$304)+SUMIF('Fabric Requirement'!$B$5:$B$304,B18,'Fabric Requirement'!$O$5:$O$304)) | I18: =IF(B18="","",SUMIF('Fabric PO'!$B$5:$B$304,B18,'Fabric PO'!$H$5:$H$304)) | J18: =IF(B18="","",SUMIF('Mill Production'!$C$5:$C$304,B18,'Mill Production'!$I$5:$I$304)) | K18: =IF(B18="","",IF(COUNTIF('Mill Test'!$C$5:$C$304,B18)=0,"Pending",IF(COUNTIFS('Mill Test'!$C$5:$C$304,B18,'Mill Test'!$T$5:$T$304,"Failed")>0,"Failed","Passed"))) | L18: =IF(B18="","",SUMIF('Fabric Shipment'!$C$5:$C$304,B18,'Fabric Shipment'!$G$5:$G$304)) | M18: =IF(B18="","",SUMIF('Fabric Shipment'!$C$5:$C$304,B18,'Fabric Shipment'!$R$5:$R$304)) | N18: =IF(B18="","",SUMIF('Fabric Receiving'!$E$5:$E$304,B18,'Fabric Receiving'!$H$5:$H$304)) | O18: =IF(B18="","",SUMIF('Fabric Receiving'!$E$5:$E$304,B18,'Fabric Receiving'!$I$5:$I$304)) | P18: =IF(B18="","",IF(COUNTIF('Four-Point'!$E$5:$E$304,B18)=0,"Pending",IF(COUNTIFS('Four-Point'!$E$5:$E$304,B18,'Four-Point'!$T$5:$T$304,"Failed")>0,"Failed","Passed"))) | Q18: =IF(B18="","",IF(COUNTIF('Internal Test'!$D$5:$D$304,B18)=0,"Pending",IF(COUNTIFS('Internal Test'!$D$5:$D$304,B18,'Internal Test'!$AA$5:$AA$304,"Failed")>0,"Failed","Passed"))) | R18: =IF(B18="","",IF(COUNTIF('Shade Match'!$C$5:$C$304,B18)=0,"Pending",IF(COUNTIFS('Shade Match'!$C$5:$C$304,B18,'Shade Match'!$Q$5:$Q$304,"Failed")>0,"Failed","Approved"))) | S18: =IF(B18="","",SUMIF('Fabric Inventory'!$C$5:$C$304,B18,'Fabric Inventory'!$H$5:$H$304)) | T18: =IF(B18="","",SUMIF('Fabric Inventory'!$C$5:$C$304,B18,'Fabric Inventory'!$K$5:$K$304)) | U18: =IF(B18="","",SUMIF('Fabric Inventory'!$C$5:$C$304,B18,'Fabric Inventory'!$L$5:$L$304)) | V18: =IF(B18="","",SUMIF('Fabric Inventory'!$C$5:$C$304,B18,'Fabric Inventory'!$N$5:$N$304)) | W18: =IF(B18="","",SUMIF('Fabric Inventory'!$C$5:$C$304,B18,'Fabric Inventory'!$O$5:$O$304))
A19: =IF('FGPO Master'!A13="","",'FGPO Master'!E13) | B19: =IF('FGPO Master'!A13="","",IF('FGPO Master'!D13="FGPO Pending","FGPO Pending",'FGPO Master'!B13)) | C19: =IF('FGPO Master'!A13="","",'FGPO Master'!D13) | D19: =IF('FGPO Master'!A13="","",'FGPO Master'!F13) | E19: =IF('FGPO Master'!A13="","",'FGPO Master'!G13) | F19: =IF('FGPO Master'!A13="","",'FGPO Master'!H13) | G19: =IF('FGPO Master'!A13="","",'FGPO Master'!M13) | H19: =IF(B19="","",SUMIF('Fabric Requirement'!$B$5:$B$304,B19,'Fabric Requirement'!$M$5:$M$304)+SUMIF('Fabric Requirement'!$B$5:$B$304,B19,'Fabric Requirement'!$O$5:$O$304)) | I19: =IF(B19="","",SUMIF('Fabric PO'!$B$5:$B$304,B19,'Fabric PO'!$H$5:$H$304)) | J19: =IF(B19="","",SUMIF('Mill Production'!$C$5:$C$304,B19,'Mill Production'!$I$5:$I$304)) | K19: =IF(B19="","",IF(COUNTIF('Mill Test'!$C$5:$C$304,B19)=0,"Pending",IF(COUNTIFS('Mill Test'!$C$5:$C$304,B19,'Mill Test'!$T$5:$T$304,"Failed")>0,"Failed","Passed"))) | L19: =IF(B19="","",SUMIF('Fabric Shipment'!$C$5:$C$304,B19,'Fabric Shipment'!$G$5:$G$304)) | M19: =IF(B19="","",SUMIF('Fabric Shipment'!$C$5:$C$304,B19,'Fabric Shipment'!$R$5:$R$304)) | N19: =IF(B19="","",SUMIF('Fabric Receiving'!$E$5:$E$304,B19,'Fabric Receiving'!$H$5:$H$304)) | O19: =IF(B19="","",SUMIF('Fabric Receiving'!$E$5:$E$304,B19,'Fabric Receiving'!$I$5:$I$304)) | P19: =IF(B19="","",IF(COUNTIF('Four-Point'!$E$5:$E$304,B19)=0,"Pending",IF(COUNTIFS('Four-Point'!$E$5:$E$304,B19,'Four-Point'!$T$5:$T$304,"Failed")>0,"Failed","Passed"))) | Q19: =IF(B19="","",IF(COUNTIF('Internal Test'!$D$5:$D$304,B19)=0,"Pending",IF(COUNTIFS('Internal Test'!$D$5:$D$304,B19,'Internal Test'!$AA$5:$AA$304,"Failed")>0,"Failed","Passed"))) | R19: =IF(B19="","",IF(COUNTIF('Shade Match'!$C$5:$C$304,B19)=0,"Pending",IF(COUNTIFS('Shade Match'!$C$5:$C$304,B19,'Shade Match'!$Q$5:$Q$304,"Failed")>0,"Failed","Approved"))) | S19: =IF(B19="","",SUMIF('Fabric Inventory'!$C$5:$C$304,B19,'Fabric Inventory'!$H$5:$H$304)) | T19: =IF(B19="","",SUMIF('Fabric Inventory'!$C$5:$C$304,B19,'Fabric Inventory'!$K$5:$K$304)) | U19: =IF(B19="","",SUMIF('Fabric Inventory'!$C$5:$C$304,B19,'Fabric Inventory'!$L$5:$L$304)) | V19: =IF(B19="","",SUMIF('Fabric Inventory'!$C$5:$C$304,B19,'Fabric Inventory'!$N$5:$N$304)) | W19: =IF(B19="","",SUMIF('Fabric Inventory'!$C$5:$C$304,B19,'Fabric Inventory'!$O$5:$O$304))
A20: =IF('FGPO Master'!A14="","",'FGPO Master'!E14) | B20: =IF('FGPO Master'!A14="","",IF('FGPO Master'!D14="FGPO Pending","FGPO Pending",'FGPO Master'!B14)) | C20: =IF('FGPO Master'!A14="","",'FGPO Master'!D14) | D20: =IF('FGPO Master'!A14="","",'FGPO Master'!F14) | E20: =IF('FGPO Master'!A14="","",'FGPO Master'!G14) | F20: =IF('FGPO Master'!A14="","",'FGPO Master'!H14) | G20: =IF('FGPO Master'!A14="","",'FGPO Master'!M14) | H20: =IF(B20="","",SUMIF('Fabric Requirement'!$B$5:$B$304,B20,'Fabric Requirement'!$M$5:$M$304)+SUMIF('Fabric Requirement'!$B$5:$B$304,B20,'Fabric Requirement'!$O$5:$O$304)) | I20: =IF(B20="","",SUMIF('Fabric PO'!$B$5:$B$304,B20,'Fabric PO'!$H$5:$H$304)) | J20: =IF(B20="","",SUMIF('Mill Production'!$C$5:$C$304,B20,'Mill Production'!$I$5:$I$304)) | K20: =IF(B20="","",IF(COUNTIF('Mill Test'!$C$5:$C$304,B20)=0,"Pending",IF(COUNTIFS('Mill Test'!$C$5:$C$304,B20,'Mill Test'!$T$5:$T$304,"Failed")>0,"Failed","Passed"))) | L20: =IF(B20="","",SUMIF('Fabric Shipment'!$C$5:$C$304,B20,'Fabric Shipment'!$G$5:$G$304)) | M20: =IF(B20="","",SUMIF('Fabric Shipment'!$C$5:$C$304,B20,'Fabric Shipment'!$R$5:$R$304)) | N20: =IF(B20="","",SUMIF('Fabric Receiving'!$E$5:$E$304,B20,'Fabric Receiving'!$H$5:$H$304)) | O20: =IF(B20="","",SUMIF('Fabric Receiving'!$E$5:$E$304,B20,'Fabric Receiving'!$I$5:$I$304)) | P20: =IF(B20="","",IF(COUNTIF('Four-Point'!$E$5:$E$304,B20)=0,"Pending",IF(COUNTIFS('Four-Point'!$E$5:$E$304,B20,'Four-Point'!$T$5:$T$304,"Failed")>0,"Failed","Passed"))) | Q20: =IF(B20="","",IF(COUNTIF('Internal Test'!$D$5:$D$304,B20)=0,"Pending",IF(COUNTIFS('Internal Test'!$D$5:$D$304,B20,'Internal Test'!$AA$5:$AA$304,"Failed")>0,"Failed","Passed"))) | R20: =IF(B20="","",IF(COUNTIF('Shade Match'!$C$5:$C$304,B20)=0,"Pending",IF(COUNTIFS('Shade Match'!$C$5:$C$304,B20,'Shade Match'!$Q$5:$Q$304,"Failed")>0,"Failed","Approved"))) | S20: =IF(B20="","",SUMIF('Fabric Inventory'!$C$5:$C$304,B20,'Fabric Inventory'!$H$5:$H$304)) | T20: =IF(B20="","",SUMIF('Fabric Inventory'!$C$5:$C$304,B20,'Fabric Inventory'!$K$5:$K$304)) | U20: =IF(B20="","",SUMIF('Fabric Inventory'!$C$5:$C$304,B20,'Fabric Inventory'!$L$5:$L$304)) | V20: =IF(B20="","",SUMIF('Fabric Inventory'!$C$5:$C$304,B20,'Fabric Inventory'!$N$5:$N$304)) | W20: =IF(B20="","",SUMIF('Fabric Inventory'!$C$5:$C$304,B20,'Fabric Inventory'!$O$5:$O$304))
A21: =IF('FGPO Master'!A15="","",'FGPO Master'!E15) | B21: =IF('FGPO Master'!A15="","",IF('FGPO Master'!D15="FGPO Pending","FGPO Pending",'FGPO Master'!B15)) | C21: =IF('FGPO Master'!A15="","",'FGPO Master'!D15) | D21: =IF('FGPO Master'!A15="","",'FGPO Master'!F15) | E21: =IF('FGPO Master'!A15="","",'FGPO Master'!G15) | F21: =IF('FGPO Master'!A15="","",'FGPO Master'!H15) | G21: =IF('FGPO Master'!A15="","",'FGPO Master'!M15) | H21: =IF(B21="","",SUMIF('Fabric Requirement'!$B$5:$B$304,B21,'Fabric Requirement'!$M$5:$M$304)+SUMIF('Fabric Requirement'!$B$5:$B$304,B21,'Fabric Requirement'!$O$5:$O$304)) | I21: =IF(B21="","",SUMIF('Fabric PO'!$B$5:$B$304,B21,'Fabric PO'!$H$5:$H$304)) | J21: =IF(B21="","",SUMIF('Mill Production'!$C$5:$C$304,B21,'Mill Production'!$I$5:$I$304)) | K21: =IF(B21="","",IF(COUNTIF('Mill Test'!$C$5:$C$304,B21)=0,"Pending",IF(COUNTIFS('Mill Test'!$C$5:$C$304,B21,'Mill Test'!$T$5:$T$304,"Failed")>0,"Failed","Passed"))) | L21: =IF(B21="","",SUMIF('Fabric Shipment'!$C$5:$C$304,B21,'Fabric Shipment'!$G$5:$G$304)) | M21: =IF(B21="","",SUMIF('Fabric Shipment'!$C$5:$C$304,B21,'Fabric Shipment'!$R$5:$R$304)) | N21: =IF(B21="","",SUMIF('Fabric Receiving'!$E$5:$E$304,B21,'Fabric Receiving'!$H$5:$H$304)) | O21: =IF(B21="","",SUMIF('Fabric Receiving'!$E$5:$E$304,B21,'Fabric Receiving'!$I$5:$I$304)) | P21: =IF(B21="","",IF(COUNTIF('Four-Point'!$E$5:$E$304,B21)=0,"Pending",IF(COUNTIFS('Four-Point'!$E$5:$E$304,B21,'Four-Point'!$T$5:$T$304,"Failed")>0,"Failed","Passed"))) | Q21: =IF(B21="","",IF(COUNTIF('Internal Test'!$D$5:$D$304,B21)=0,"Pending",IF(COUNTIFS('Internal Test'!$D$5:$D$304,B21,'Internal Test'!$AA$5:$AA$304,"Failed")>0,"Failed","Passed"))) | R21: =IF(B21="","",IF(COUNTIF('Shade Match'!$C$5:$C$304,B21)=0,"Pending",IF(COUNTIFS('Shade Match'!$C$5:$C$304,B21,'Shade Match'!$Q$5:$Q$304,"Failed")>0,"Failed","Approved"))) | S21: =IF(B21="","",SUMIF('Fabric Inventory'!$C$5:$C$304,B21,'Fabric Inventory'!$H$5:$H$304)) | T21: =IF(B21="","",SUMIF('Fabric Inventory'!$C$5:$C$304,B21,'Fabric Inventory'!$K$5:$K$304)) | U21: =IF(B21="","",SUMIF('Fabric Inventory'!$C$5:$C$304,B21,'Fabric Inventory'!$L$5:$L$304)) | V21: =IF(B21="","",SUMIF('Fabric Inventory'!$C$5:$C$304,B21,'Fabric Inventory'!$N$5:$N$304)) | W21: =IF(B21="","",SUMIF('Fabric Inventory'!$C$5:$C$304,B21,'Fabric Inventory'!$O$5:$O$304))
A22: =IF('FGPO Master'!A16="","",'FGPO Master'!E16) | B22: =IF('FGPO Master'!A16="","",IF('FGPO Master'!D16="FGPO Pending","FGPO Pending",'FGPO Master'!B16)) | C22: =IF('FGPO Master'!A16="","",'FGPO Master'!D16) | D22: =IF('FGPO Master'!A16="","",'FGPO Master'!F16) | E22: =IF('FGPO Master'!A16="","",'FGPO Master'!G16) | F22: =IF('FGPO Master'!A16="","",'FGPO Master'!H16) | G22: =IF('FGPO Master'!A16="","",'FGPO Master'!M16) | H22: =IF(B22="","",SUMIF('Fabric Requirement'!$B$5:$B$304,B22,'Fabric Requirement'!$M$5:$M$304)+SUMIF('Fabric Requirement'!$B$5:$B$304,B22,'Fabric Requirement'!$O$5:$O$304)) | I22: =IF(B22="","",SUMIF('Fabric PO'!$B$5:$B$304,B22,'Fabric PO'!$H$5:$H$304)) | J22: =IF(B22="","",SUMIF('Mill Production'!$C$5:$C$304,B22,'Mill Production'!$I$5:$I$304)) | K22: =IF(B22="","",IF(COUNTIF('Mill Test'!$C$5:$C$304,B22)=0,"Pending",IF(COUNTIFS('Mill Test'!$C$5:$C$304,B22,'Mill Test'!$T$5:$T$304,"Failed")>0,"Failed","Passed"))) | L22: =IF(B22="","",SUMIF('Fabric Shipment'!$C$5:$C$304,B22,'Fabric Shipment'!$G$5:$G$304)) | M22: =IF(B22="","",SUMIF('Fabric Shipment'!$C$5:$C$304,B22,'Fabric Shipment'!$R$5:$R$304)) | N22: =IF(B22="","",SUMIF('Fabric Receiving'!$E$5:$E$304,B22,'Fabric Receiving'!$H$5:$H$304)) | O22: =IF(B22="","",SUMIF('Fabric Receiving'!$E$5:$E$304,B22,'Fabric Receiving'!$I$5:$I$304)) | P22: =IF(B22="","",IF(COUNTIF('Four-Point'!$E$5:$E$304,B22)=0,"Pending",IF(COUNTIFS('Four-Point'!$E$5:$E$304,B22,'Four-Point'!$T$5:$T$304,"Failed")>0,"Failed","Passed"))) | Q22: =IF(B22="","",IF(COUNTIF('Internal Test'!$D$5:$D$304,B22)=0,"Pending",IF(COUNTIFS('Internal Test'!$D$5:$D$304,B22,'Internal Test'!$AA$5:$AA$304,"Failed")>0,"Failed","Passed"))) | R22: =IF(B22="","",IF(COUNTIF('Shade Match'!$C$5:$C$304,B22)=0,"Pending",IF(COUNTIFS('Shade Match'!$C$5:$C$304,B22,'Shade Match'!$Q$5:$Q$304,"Failed")>0,"Failed","Approved"))) | S22: =IF(B22="","",SUMIF('Fabric Inventory'!$C$5:$C$304,B22,'Fabric Inventory'!$H$5:$H$304)) | T22: =IF(B22="","",SUMIF('Fabric Inventory'!$C$5:$C$304,B22,'Fabric Inventory'!$K$5:$K$304)) | U22: =IF(B22="","",SUMIF('Fabric Inventory'!$C$5:$C$304,B22,'Fabric Inventory'!$L$5:$L$304)) | V22: =IF(B22="","",SUMIF('Fabric Inventory'!$C$5:$C$304,B22,'Fabric Inventory'!$N$5:$N$304)) | W22: =IF(B22="","",SUMIF('Fabric Inventory'!$C$5:$C$304,B22,'Fabric Inventory'!$O$5:$O$304))
